Workbook

Sheet Purchases
B1: YASH ENTERPRISES | C1: JUBILANT
B2: Date | C2: 31.03.2026
B3: Bill No | C3: UP251006053
A4: Sr. No. | B4: Jubifix | C4: Qty | D4: Qty | E4: Qty | F4: Qty | G4: Qty | H4: Qty | I4: Qty | J4: Qty | K4: Qty | L4: Qty | M4: Qty | N4: Qty | O4: Qty | P4: Qty | Q4: Qty | R4: Qty | S4: Qty | T4: Qty | U4: Qty | V4: Grand Total
A5: 1 | B5: JUBIFIX ACRO BLACK 450 GMS | U5: 45 | V5: =sum(C5:U5) -> 45
A6: 2 | B6: JUBIFIX ACRO WHITE 450 GMS | V6: =sum(C6:U6) -> 0
A7: 3 | B7: JUBIFIX CONSTRO 360 GMS | V7: =sum(C7:U7) -> 0
A8: 4 | B8: JUBIFIX CRAXO 1KG | V8: =sum(C8:U8) -> 0
A9: 5 | B9: JUBIFIX CRAXO 500 GMS | V9: =sum(C9:U9) -> 0
A10: 6 | B10: JUBIFIX GP PRO BLACK 260 ML | V10: =sum(C10:U10) -> 0
A11: 7 | B11: JUBIFIX GP PRO CLEAR 260 ML | V11: =sum(C11:U11) -> 0
A12: 8 | B12: JUBIFIX GP PRO WHITE 260 ML | V12: =sum(C12:U12) -> 0
A13: 9 | B13: JUBIFIX GP ULTRA BLACK | V13: =sum(C13:U13) -> 0
A14: 10 | B14: JUBIFIX GP ULTRA CLEAR | V14: =sum(C14:U14) -> 0
A15: 11 | B15: JUBIFIX GP ULTRA WHITE | V15: =sum(C15:U15) -> 0
A16: 12 | B16: JUBIFIX NEUTRO BLACK 270 ML | V16: =sum(C16:U16) -> 0
A17: 13 | B17: JUBIFIX NEUTRO CLEAR 270 ML | V17: =sum(C17:U17) -> 0
... A93: 89 | B93: WATER JUG CPD | V93: =sum(C93:U93) -> 0
B94: Grand Total | C94: =SUM(C5:C93) -> 0 | D94: =SUM(D5:D93) -> 0 | E94: =SUM(E5:E93) -> 0 | F94: =SUM(F5:F93) -> 0 | G94: =SUM(G5:G93) -> 0 | H94: =SUM(H5:H93) -> 0 | I94: =SUM(I5:I93) -> 0 | J94: =SUM(J5:J93) -> 0 | ... U94: =SUM(U5:U93) -> 45 | V94: =sum(C94:U94) -> 45

Sheet Sales
B1: YASH ENTERPRISES | C1: JUBILANT
B2: Date
B3: DELIVERY CHALLAN NO | C3: 1 | D3: 2 | E3: 3 | F3: 4 | G3: 5 | H3: 6 | I3: 7 | J3: 8 | K3: 9 | L3: 10 | M3: 11 | N3: 12 | O3: 13 | P3: 14 | Q3: 15 | R3: 16 | S3: 17 | T3: 18 | U3: 19 | V3: 20 | W3: 21 | X3: 22 | Y3: 23 | Z3: 24 | AA3: 25 | AB3: 26 | AC3: 27 | AD3: 28 | AE3: 29 | AF3: 30
A4: Sr. No. | B4: Jubifix | C4: Qty | D4: Qty | E4: Qty | F4: Qty | G4: Qty | H4: Qty | I4: Qty | J4: Qty | K4: Qty | L4: Qty | M4: Qty | N4: Qty | O4: Qty | P4: Qty | Q4: Qty | R4: Qty | S4: Qty | T4: Qty | U4: Qty | V4: Qty | W4: Qty | X4: Qty | Y4: Qty | Z4: Qty | AA4: Qty | AB4: Qty | AC4: Qty | AD4: Qty | AE4: Qty | AF4: Qty | AG4: Grand Total | AH4: BASIC AMT
A5: 1 | B5: JUBIFIX ACRO BLACK 450 GMS | C5: 24 | H5: 120 | I5: 20 | AG5: =sum(C5:AF5) -> 164 | AH5: =AG5 *5.93 -> 972.52
A6: 2 | B6: JUBIFIX ACRO WHITE 450 GMS | H6: 48 | AG6: =sum(C6:AF6) -> 48 | AH6: =AG6 *63.5 -> 3048
A7: 3 | B7: JUBIFIX CONSTRO 360 GMS | AG7: =sum(C7:AF7) -> 0 | AH7: =AG7 *63.5 -> 0
A8: 4 | B8: JUBIFIX CRAXO 1KG | E8: 12 | AG8: =sum(C8:AF8) -> 12 | AH8: =AG8 *185.76 -> 2229.12
A9: 5 | B9: JUBIFIX CRAXO 500 GMS | AG9: =sum(C9:AF9) -> 0 | AH9: =AG9 *63.5 -> 0
A10: 6 | B10: JUBIFIX GP PRO BLACK 260 ML | AG10: =sum(C10:AF10) -> 0 | AH10: =AG10 *63.5 -> 0
A11: 7 | B11: JUBIFIX GP PRO CLEAR 260 ML | AG11: =sum(C11:AF11) -> 0 | AH11: =AG11 *63.5 -> 0
A12: 8 | B12: JUBIFIX GP PRO WHITE 260 ML | AG12: =sum(C12:AF12) -> 0 | AH12: =AG12 *63.5 -> 0
A13: 9 | B13: JUBIFIX GP ULTRA BLACK | AG13: =sum(C13:AF13) -> 0 | AH13: =AG13 *63.5 -> 0
A14: 10 | B14: JUBIFIX GP ULTRA CLEAR | AG14: =sum(C14:AF14) -> 0 | AH14: =AG14 *63.5 -> 0
A15: 11 | B15: JUBIFIX GP ULTRA WHITE | AG15: =sum(C15:AF15) -> 0 | AH15: =AG15 *63.5 -> 0
A16: 12 | B16: JUBIFIX NEUTRO BLACK 270 ML | AG16: =sum(C16:AF16) -> 0 | AH16: =AG16 *17.8 -> 0
A17: 13 | B17: JUBIFIX NEUTRO CLEAR 270 ML | AG17: =sum(C17:AF17) -> 0 | AH17: =AG17 *63.5 -> 0
A18: 14 | B18: JUBIFIX NEUTRO WHITE 270 ML | AG18: =sum(C18:AF18) -> 0 | AH18: =AG18 *63.5 -> 0
A19: 15 | B19: JUBIFIX PASTO 450 GM | AG19: =sum(C19:AF19) -> 0 | AH19: =AG19 *268.44 -> 0
A20: 16 | B20: JUBIFIX PU BLACK-600 ML | AG20: =sum(C20:AF20) -> 0 | AH20: =AG20 *63.5 -> 0
A21: 17 | B21: JUBIFIX WEATHO BLACK 270 ML | AG21: =sum(C21:AF21) -> 0 | AH21: =AG21 *33.9 -> 0
A22: 18 | B22: JUBIFIX WEATHO CLEAR 270 ML | AG22: =sum(C22:AF22) -> 0 | AH22: =AG22 *63.5 -> 0
A23: 19 | B23: JUBIFIX WEATHO WHITE 270 ML | AG23: =sum(C23:AF23) -> 0 | AH23: =AG23 *79.66 -> 0
A24: 20 | B24: BOTTLE GIFT SET | AG24: =sum(C24:AF24) -> 0 | AH24: =AG24 *63.5 -> 0
A25: 21 | B25: DUFFLE BAG | AG25: =sum(C25:AF25) -> 0 | AH25: =AG25 *63.5 -> 0
A26: 22 | B26: GIFT SET 5% | AG26: =sum(C26:AF26) -> 0 | AH26: =AG26 *63.5 -> 0
A27: 23 | B27: JUBI 90 (292 GM / 400 ML) | AG27: =sum(C27:AF27) -> 0 | AH27: =AG27 *63.5 -> 0
A28: 24 | B28: JUBI 90 - 32 GMS | G28: 20 | AG28: =sum(C28:AF28) -> 20 | AH28: =AG28 *63.5 -> 1270
A29: 25 | B29: JUBI 90 - 64 GMS | AG29: =sum(C29:AF29) -> 0 | AH29: =AG29 *63.5 -> 0
A30: 26 | B30: JUBIBOND ALL IN ONE 100 ML | D30: 12 | AG30: =sum(C30:AF30) -> 12 | AH30: =AG30 *63.5 -> 762
A31: 27 | B31: JUBIBOND ALL IN ONE 50 ML | D31: 12 | AG31: =sum(C31:AF31) -> 12 | AH31: =AG31 *61.82 -> 741.84
A32: 28 | B32: JUBIBOND CPVC 100 ML | D32: 12 | AG32: =sum(C32:AF32) -> 12 | AH32: =AG32 *63.5 -> 762
A33: 29 | B33: JUBIBOND CPVC 10 ML | AG33: =sum(C33:AF33) -> 0 | AH33: =AG33 *63.5 -> 0
A34: 30 | B34: JUBIBOND CPVC 200 ML | AG34: =sum(C34:AF34) -> 0 | AH34: =AG34 *75.6 -> 0
A35: 31 | B35: JUBIBOND CPVC 20 ML | AG35: =sum(C35:AF35) -> 0 | AH35: =AG35 *63.5 -> 0
A36: 32 | B36: JUBIBOND CPVC 50 ML | AG36: =sum(C36:AF36) -> 0 | AH36: =AG36 *63.5 -> 0
A37: 33 | B37: JUBIBOND PVC 100 ML | AG37: =sum(C37:AF37) -> 0 | AH37: =AG37 *63.5 -> 0
A38: 34 | B38: JUBIBOND PVC 200 ML | AG38: =sum(C38:AF38) -> 0 | AH38: =AG38 *63.5 -> 0
A39: 35 | B39: JUBIBOND PVC 50 ML | AG39: =sum(C39:AF39) -> 0 | AH39: =AG39 *580.5 -> 0
A40: 36 | B40: JUBIBOND PVC TUBE 10 ML | AG40: =sum(C40:AF40) -> 0 | AH40: =AG40 *63.5 -> 0
...

Sheet JUBILANT STOCK APRIL 26
B1: YASH ENTERPRISES
B2: JUBILANT STOCK APRIL 2026
A3: Sr. No. | B3: Jubifix | C3: Opening Quantity | D3: Purchases | E3: Sales | F3: Balance
A4: 1 | B4: JUBIFIX ACRO BLACK 450 GMS | C4: 47 | D4: =Purchases!V24 -> 0 | E4: =Sales!AG5 -> 164 | F4: =C4+D4-E4 -> -117
A5: 2 | B5: JUBIFIX ACRO WHITE 450 GMS | C5: 30 | D5: =Purchases!V25 -> 0 | E5: =Sales!AG6 -> 48 | F5: =C5+D5-E5 -> -18
A6: 3 | B6: JUBIFIX CONSTRO 360 GMS | D6: =Purchases!V26 -> 0 | E6: =Sales!AG7 -> 0 | F6: =C6+D6-E6 -> 0
A7: 4 | B7: JUBIFIX CRAXO 1KG | C7: 509 | D7: =Purchases!V28 -> 0 | E7: =Sales!AG8 -> 12 | F7: =C7+D7-E7 -> 497
A8: 5 | B8: JUBIFIX CRAXO 500 GMS | C8: 25 | D8: =Purchases!V29 -> 0 | E8: =Sales!AG9 -> 0 | F8: =C8+D8-E8 -> 25
A9: 6 | B9: JUBIFIX GP PRO BLACK 260 ML | D9: =Purchases!V27 -> 0 | E9: =Sales!AG10 -> 0 | F9: =C9+D9-E9 -> 0
A10: 7 | B10: JUBIFIX GP PRO CLEAR 260 ML | C10: 288 | D10: =Purchases!V30 -> 0 | E10: =Sales!AG11 -> 0 | F10: =C10+D10-E10 -> 288
A11: 8 | B11: JUBIFIX GP PRO WHITE 260 ML | C11: 336 | D11: =Purchases!V31 -> 0 | E11: =Sales!AG12 -> 0 | F11: =C11+D11-E11 -> 336
A12: 9 | B12: JUBIFIX GP ULTRA BLACK | C12: 425 | D12: =Purchases!V33 -> 0 | E12: =Sales!AG13 -> 0 | F12: =C12+D12-E12 -> 425
A13: 10 | B13: JUBIFIX GP ULTRA CLEAR | C13: 68 | D13: =Purchases!V32 -> 0 | E13: =Sales!AG14 -> 0 | F13: =C13+D13-E13 -> 68
A14: 11 | B14: JUBIFIX GP ULTRA WHITE | C14: 475 | D14: =Purchases!V35 -> 0 | E14: =Sales!AG15 -> 0 | F14: =C14+D14-E14 -> 475
A15: 12 | B15: JUBIFIX NEUTRO BLACK 270 ML | C15: 96 | D15: =Purchases!V34 -> 0 | E15: =Sales!AG16 -> 0 | F15: =C15+D15-E15 -> 96
A16: 13 | B16: JUBIFIX NEUTRO CLEAR 270 ML | C16: 168 | D16: =Purchases!V36 -> 0 | E16: =Sales!AG17 -> 0 | F16: =C16+D16-E16 -> 168
A17: 14 | B17: JUBIFIX NEUTRO WHITE 270 ML | D17: =Purchases!V37 -> 0 | E17: =Sales!AG18 -> 0 | F17: =C17+D17-E17 -> 0
A18: 15 | B18: JUBIFIX PASTO 450 GM | D18: =Purchases!V38 -> 0 | E18: =Sales!AG19 -> 0 | F18: =C18+D18-E18 -> 0
A19: 16 | B19: JUBIFIX PU BLACK-600 ML | C19: 48 | D19: =Purchases!V39 -> 0 | E19: =Sales!AG20 -> 0 | F19: =C19+D19-E19 -> 48
A20: 17 | B20: JUBIFIX WEATHO BLACK 270 ML | C20: 400 | D20: =Purchases!V40 -> 0 | E20: =Sales!AG21 -> 0 | F20: =C20+D20-E20 -> 400
A21: 18 | B21: JUBIFIX WEATHO CLEAR 270 ML | D21: =Purchases!V42 -> 0 | E21: =Sales!AG22 -> 0 | F21: =C21+D21-E21 -> 0
A22: 19 | B22: JUBIFIX WEATHO WHITE 270 ML | D22: =Purchases!V41 -> 0 | E22: =Sales!AG23 -> 0 | F22: =C22+D22-E22 -> 0
A23: 20 | B23: BOTTLE GIFT SET | D23: =Purchases!V43 -> 0 | E23: =Sales!AG24 -> 0 | F23: =C23+D23-E23 -> 0
A24: 21 | B24: DUFFLE BAG | C24: 96 | D24: =Purchases!V44 -> 0 | E24: =Sales!AG25 -> 0 | F24: =C24+D24-E24 -> 96
A25: 22 | B25: GIFT SET 5% | C25: 50 | D25: =Purchases!V45 -> 0 | E25: =Sales!AG26 -> 0 | F25: =C25+D25-E25 -> 50
A26: 23 | B26: JUBI 90 (292 GM / 400 ML) | C26: 8 | D26: =Purchases!V47 -> 0 | E26: =Sales!AG27 -> 0 | F26: =C26+D26-E26 -> 8
A27: 24 | B27: JUBI 90 - 32 GMS | C27: 94 | D27: =Purchases!V46 -> 0 | E27: =Sales!AG28 -> 20 | F27: =C27+D27-E27 -> 74
A28: 25 | B28: JUBI 90 - 64 GMS | C28: 600 | D28: =Purchases!V48 -> 0 | E28: =Sales!AG29 -> 0 | F28: =C28+D28-E28 -> 600
A29: 26 | B29: JUBIBOND ALL IN ONE 100 ML | C29: 125 | D29: =Purchases!V49 -> 0 | E29: =Sales!AG30 -> 12 | F29: =C29+D29-E29 -> 113
A30: 27 | B30: JUBIBOND ALL IN ONE 50 ML | C30: 768 | D30: =Purchases!V5 -> 45 | E30: =Sales!AG31 -> 12 | F30: =C30+D30-E30 -> 801
A31: 28 | B31: JUBIBOND CPVC 100 ML | C31: 1003 | D31: =Purchases!V6 -> 0 | E31: =Sales!AG32 -> 12 | F31: =C31+D31-E31 -> 991
A32: 29 | B32: JUBIBOND CPVC 10 ML | C32: 197 | D32: =Purchases!V7 -> 0 | E32: =Sales!AG33 -> 0 | F32: =C32+D32-E32 -> 197
A33: 30 | B33: JUBIBOND CPVC 200 ML | C33: 24 | D33: =Purchases!V8 -> 0 | E33: =Sales!AG34 -> 0 | F33: =C33+D33-E33 -> 24
A34: 31 | B34: JUBIBOND CPVC 20 ML | C34: 7 | D34: =Purchases!V9 -> 0 | E34: =Sales!AG35 -> 0 | F34: =C34+D34-E34 -> 7
A35: 32 | B35: JUBIBOND CPVC 50 ML | C35: 120 | D35: =Purchases!V10 -> 0 | E35: =Sales!AG36 -> 0 | F35: =C35+D35-E35 -> 120
A36: 33 | B36: JUBIBOND PVC 100 ML | C36: 312 | D36: =Purchases!V11 -> 0 | E36: =Sales!AG37 -> 0 | F36: =C36+D36-E36 -> 312
A37: 34 | B37: JUBIBOND PVC 200 ML | C37: 120 | D37: =Purchases!V12 -> 0 | E37: =Sales!AG38 -> 0 | F37: =C37+D37-E37 -> 120
A38: 35 | B38: JUBIBOND PVC 50 ML | C38: 96 | D38: =Purchases!V13 -> 0 | E38: =Sales!AG39 -> 0 | F38: =C38+D38-E38 -> 96
A39: 36 | B39: JUBIBOND PVC TUBE 10 ML | D39: =Purchases!V14 -> 0 | E39: =Sales!AG40 -> 0 | F39: =C39+D39-E39 -> 0
A40: 37 | B40: JUBIBOND UPVC 100 ML | C40: 76 | D40: =Purchases!V15 -> 0 | E40: =Sales!AG41 -> 0 | F40: =C40+D40-E40 -> 76
...

Sheet Sheet2

Sheet JUBILANT
A1: YASH ENTERPRISES
A2: 52/1, Rupa Bhavani Road,
A3: In Front of Rupa Bhavani Water Works,
A4: Bhavani Peth, SOLAPUR - 413 002
A5: JUBILANT
A6: Stock Group Summary
A7: 1-Apr-25 to 4-Apr-26
B8: JUBILANT
B9: YASH ENTERPRISES - 2024-25
A10: Particulars | B10: 1-Apr-25 to 4-Apr-26
B11: Closing Balance
B12: Quantity | C12: Rate | D12: Value
A13: Jubifix | D13: 335157.32
A14: JUBIFIX ACRO BLACK 450 GMS | B14: 768 | C14: 53.67 | D14: 41220.5
A15: JUBIFIX ACRO WHITE 450 GMS | B15: 1003 | C15: 53.01 | D15: 53166.33
A16: JUBIFIX CONSTRO 360 GMS | B16: 197 | C16: 116.67 | D16: 22983.99
A17: JUBIFIX CRAXO 1KG | B17: 24 | C17: 225.85 | D17: 5420.33
A18: JUBIFIX CRAXO 500 GMS | B18: 7 | C18: 122.79 | D18: 859.53
A19: JUBIFIX GP PRO BLACK 260 ML | B19: 120 | C19: 76 | D19: 9120.15
A20: JUBIFIX GP PRO CLEAR 260 ML | B20: 312 | C20: 76.14 | D20: 23755.22
A21: JUBIFIX GP PRO WHITE 260 ML | B21: 120 | C21: 76 | D21: 9120.15
A22: JUBIFIX GP ULTRA BLACK | B22: 96 | C22: 78.2 | D22: 7507.2
A23: JUBIFIX GP ULTRA CLEAR
A24: JUBIFIX GP ULTRA WHITE | B24: 76 | C24: 78.2 | D24: 5943.2
A25: JUBIFIX NEUTRO BLACK 270 ML | B25: 72 | C25: 102 | D25: 7344
A26: JUBIFIX NEUTRO CLEAR 270 ML | B26: 24 | C26: 108.86 | D26: 2612.57
A27: JUBIFIX NEUTRO WHITE 270 ML | B27: 72 | C27: 105 | D27: 7560
A28: JUBIFIX PASTO 450 GM | B28: 190 | C28: 207.31 | D28: 39389.79
A29: JUBIFIX PU BLACK-600 ML | B29: 16 | C29: 250 | D29: 4000
A30: JUBIFIX WEATHO BLACK 270 ML | B30: 576 | C30: 125.84 | D30: 72483.59
A31: JUBIFIX WEATHO CLEAR 270 ML | B31: 96 | C31: 121.15 | D31: 11630.77
A32: JUBIFIX WEATHO WHITE 270 ML | B32: 96 | C32: 115 | D32: 11040
A33: BOTTLE GIFT SET | B33: 47 | C33: 1 | D33: 47
A34: DUFFLE BAG | B34: 30 | C34: 1 | D34: 30
A35: GIFT SET 5%
A36: JUBI 90 (292 GM / 400 ML)
A37: JUBI 90 - 32 GMS | B37: 509 | C37: 40.66 | D37: 20698.12
A38: JUBI 90 - 64 GMS | B38: 25 | C38: 60.28 | D38: 1506.99
A39: JUBIBOND ALL IN ONE 100 ML | B39: 288 | C39: 70.43 | D39: 20282.83
A40: JUBIBOND ALL IN ONE 50 ML | B40: 336 | C40: 38.99 | D40: 13099.03
...

Sheet Sheet3
A1: Content | B1: Type | C1: Details | D1: Owner | E1: Status | F1: Post date | G1: File | H1: Notes
B2: Email | E2: New
B3: Social media | E3: In progress
B4: TV | E4: Under review
B5: Blog post | E5: Published
B6: All | E6: Suspended
E7: Paused

Sheet Sheet4
A1: Feature | B1: Category | C1: Status | D1: Owner | E1: Size | F1: Launch | G1: Notes
B2: Category 1 | C2: Not started | E2: XS | F2: Q1
B3: Category 2 | C3: In progress | E3: S | F3: Q2
B4: Category 3 | C4: Blocked | E4: M | F4: Q3
B5: Category 4 | C5: Launched | E5: L | F5: Q4
E6: XL
E7: XXL

Sheet Sheet5
A1: Feature | B1: Category | C1: Status | D1: Owner | E1: Size | F1: Launch | G1: Notes
B2: Category 1 | C2: Not started | E2: XS | F2: Q1
B3: Category 2 | C3: In progress | E3: S | F3: Q2
B4: Category 3 | C4: Blocked | E4: M | F4: Q3
B5: Category 4 | C5: Launched | E5: L | F5: Q4
E6: XL
E7: XXL

Sheet Sheet6
A1: Applicant | B1: Stage | C1: Role | D1: Team | E1: Resume | F1: Interviewer | G1: Score | H1: Notes
B2: Hire | D2: Team 1 | G2: 0
B3: Interviewing | D3: Team 2 | G3: 0
B4: Decision needed | D4: Team 3 | G4: 0
B5: No hire | D5: Team 4 | G5: 0
G6: 0
G7: 0
G8: 0
G9: 0
G10: 0
G11: 0
G12: 0
G13: 0
G14: 0
G15: 0

Sheet Sheet7
A1: Task | B1: Status | C1: Owner | D1: Stage | E1: Due date | F1: Notes
B2: Not started | D2: Pre-event
B3: In progress | D3: Day of
B4: Blocked | D4: Post-event
B5: Completed
